Workbook

Sheet DCF
A1: ASML DCF | F1: *This model is specified to the needs of ASML, please make your own changes accordingly
F2: *If any questions arise, feel free to contact: Drolwand1@luc.edu with any questions | M2: Notes
M3: *TGR Switch only works if you use the stable Company TV calc, I used the unstable for ASML here so It wont work
B4: Ticker | C4: ASML | E4: Implied Share Price | H4: =D63 -> 976.72268 | M4: *If you want to move around year, Change cell F22
B5: Date | C5: 45511 | E5: Current Share Price | H5: 843.01 | M5: *Make sure if NWC is negative you state it as such, and if it is positive you state it as such.
B6: Year End | C6: 45657 | E6: Implied Gain/Loss | H6: =(H4/H5)-1 -> 0.1586134 | M6: *The reason we use unlevered FCF is because we want to evaluate cash flows without the effect of debt or equity
M7: *We account for the debt and equity in our calculation of Enterprise Value
M8: *Whole Model is in Millions | AA8: *I just sloppily used CAGR for projections. Couldve baked in some price changes etc but I got lazy
M9: *You only need to use TGR for Stable Businesses, otherwise simply input TV into Cell R50
A10: X | B10: Assumptions | AC10: REV CAGR: | AD10: =((M21/K21)^(1/3))-1 -> 0.14484837
B11: Switches | F11: Bear Case | J11: Base Case | N11: Bull Case | AC11: COGS CAGR: | AD11: =((M23/K23)^(1/3))-1 -> 0.11479332
B13: WACC | C13: 2 | S13: * you may see some loose percentages, they are just my lazy growth rates
B14: TGR | C14: 3
J16: Taxes | L16: =WACC!E14 -> 0.1581
B17: WACC | C17: =CHOOSE($C$13,H17,L17,P17) -> 0.11140131 | F17: WACC | H17: =L17+0.5% -> 0.11640131 | J17: WACC | L17: =WACC!E19 -> 0.11140131 | N17: WACC | P17: =L17-0.5% -> 0.10640131
B18: TGR | C18: =CHOOSE($C$14,H18,L18,P18) -> 0.004 | F18: TGR | H18: =L18-0.4% -> -0.004 | J18: TGR | N18: TGR | P18: =L18+0.4% -> 0.004
L19: *Hard input TGR Only
A20: X | B20: Income Statement FYE | F20: 2019 | G20: =F20+1 -> 2020 | H20: =G20+1 -> 2021 | I20: =H20+1 -> 2022 | J20: =I20+1 -> 2023 | K20: =J20+1 -> 2024 | L20: =K20+1 -> 2025 | M20: =L20+1 -> 2026 | N20: =M20+1 -> 2027 | ... P20: =O20+1 -> 2029 | Q20: TV Year
A21: X | B21: Revenue | F21: 13229 | G21: 15931 | H21: 22005 | I21: 22265 | J21: 29792 | K21: 30342 | L21: 40940 | M21: 45529 | N21: =M21*($AD$10+1) -> 52123.801 | O21: =N21*($AD$10+1) -> 59673.849 | P21: =O21*($AD$10+1) -> 68317.508
A23: X | B23: COGS | F23: 5233 | G23: 5891 | H23: 7665 | I23: 11013 | J23: 14510 | K23: 14724 | L23: 18704 | M23: 20399 | N23: =M23*($AD$11+1) -> 22740.669 | O23: =N23*($AD$11+1) -> 25351.146 | P23: =O23*($AD$11+1) -> 28261.288
A25: X | B25: Gross Profit | F25: =F21-F23 -> 7996 | G25: =G21-G23 -> 10040 | H25: =H21-H23 -> 14340 | I25: =I21-I23 -> 11252 | J25: =J21-J23 -> 15282 | K25: =K21-K23 -> 15618 | L25: =L21-L23 -> 22236 | M25: =M21-M23 -> 25130 | ... P25: =P21-P23 -> 40056.221
A27: X | B27: OpEx | F27: =F$20 -> 2019 | G27: =G$20 -> 2020 | H27: =H$20 -> 2021 | I27: =I$20 -> 2022 | J27: =J$20 -> 2023 | K27: =K$20 -> 2024 | L27: =L$20 -> 2025 | M27: =M$20 -> 2026 | ... P27: =P$20 -> 2029 | Q27: TV Year
A28: X | B28: SG&A | F28: 2785 | G28: 3129 | H28: 3869 | I28: 4415 | J28: 5506 | K28: 5589 | L28: 6522 | M28: 6593 | N28: =M28*(1+$R$28) -> 6966.2555 | O28: =N28*(1+$R$28) -> 7360.6424 | P28: =O28*(1+$R$28) -> 7777.3571 | R28: =((M28/K28)^(1/3))-1 -> 0.056613906
A30: X | B30: Other Exp | F30: 0 | G30: 0 | H30: 0 | I30: 0 | J30: 0 | K30: 0 | L30: 0 | M30: 0 | N30: 0 | O30: 0 | P30: 0 | S30: *Other exp just baked into SG&A in ASML reporting
A32: X | B32: EBITDA | F32: =F25-F28-F30 -> 5211 | G32: =G25-G28-G30 -> 6911 | H32: =H25-H28-H30 -> 10471 | I32: =I25-I28-I30 -> 6837 | J32: =J25-J28-J30 -> 9776 | K32: =K25-K28-K30 -> 10029 | L32: =L25-L28-L30 -> 15714 | M32: =M25-M28-M30 -> 18537 | ... P32: =P25-P28-P30 -> 32278.864 | Q32: =P32*(1+R32) -> 39221.874 | R32: =((P32/K32)^(1/6))-1 -> 0.21509463
Q33: ^If need, project Terminal EBITDA here
A34: X | B34: D&A | F34: -164 | G34: -159.78 | H34: -162.94 | I34: 610 | J34: 792 | K34: 977 | L34: 1136 | M34: 1424 | N34: =M34*(1+$R$34) -> 1614.5387 | O34: =N34*(1+$R$34) -> 1830.5725 | P34: =O34*(1+$R$34) -> 2075.5128 | R34: =((M34/K34)^(1/3))-1 -> 0.13380528
A36: X | B36: OpInc | F36: =F$20 -> 2019 | G36: =G$20 -> 2020 | H36: =H$20 -> 2021 | I36: =I$20 -> 2022 | J36: =J$20 -> 2023 | K36: =K$20 -> 2024 | L36: =L$20 -> 2025 | M36: =M$20 -> 2026 | ... P36: =P$20 -> 2029 | Q36: TV Year
A37: X | B37: EBIT (A.K.A OpInc) | F37: =F32-F34 -> 5375 | G37: =G32-G34 -> 7070.78 | H37: =H32-H34 -> 10633.94 | I37: =I32-I34 -> 6227 | J37: =J32-J34 -> 8984 | K37: =K32-K34 -> 9052 | L37: =L32-L34 -> 14578 | M37: =M32-M34 -> 17113 | ... P37: =P32-P34 -> 30203.351
A39: X | B39: Taxes | F39: =F37*$L$16 -> 849.7875 | G39: =G37*$L$16 -> 1117.8903 | H39: =H37*$L$16 -> 1681.2259 | I39: =I37*$L$16 -> 984.4887 | J39: =J37*$L$16 -> 1420.3704 | K39: =K37*$L$16 -> 1431.1212 | L39: =L37*$L$16 -> 2304.7818 | M39: =M37*$L$16 -> 2705.5653 | ... P39: =P37*$L$16 -> 4775.1498
A41: X | B41: EBIAT (A.K.A NOPAT) | F41: =F37-F39 -> 4525.2125 | G41: =G37-G39 -> 5952.8897 | H41: =H37-H39 -> 8952.7141 | I41: =I37-I39 -> 5242.5113 | J41: =J37-J39 -> 7563.6296 | K41: =K37-K39 -> 7620.8788 | L41: =L37-L39 -> 12273.218 | M41: =M37-M39 -> 14407.435 | ... P41: =P37-P39 -> 25428.201
A43: X | B43: CF Stmnt Adjmnts down to FCF | F43: =F$20 -> 2019 | G43: =G$20 -> 2020 | H43: =H$20 -> 2021 | I43: =I$20 -> 2022 | J43: =J$20 -> 2023 | K43: =K$20 -> 2024 | L43: =L$20 -> 2025 | M43: =M$20 -> 2026 | ... P43: =P$20 -> 2029 | Q43: TV Year
A44: X | B44: Add back D&A | F44: =F34 -> -164 | G44: =G34 -> -159.78 | H44: =H34 -> -162.94 | I44: =I34 -> 610 | J44: =J34 -> 792 | K44: =K34 -> 977 | L44: =L34 -> 1136 | M44: =M34 -> 1424 | ... P44: =P34 -> 2075.5128
A46: X | B46: CapEx | F46: 992 | G46: 1140 | H46: 1112 | I46: 1387 | J46: 2374 | K46: 2110 | L46: 2232 | M46: 2338 | N46: =M46*(1+$Q$46) -> 2419.349 | O46: =N46*(1+$Q$46) -> 2503.5285 | P46: =O46*(1+$Q$46) -> 2590.637 | Q46: =((M46/K46)^(1/3))-1 -> 0.034794275
A48: X | B48: Change in NWC | F48: 125 | G48: 606 | H48: 5785 | I48: 2567 | J48: -3961 | K48: 703 | L48: 388 | M48: 1327 | N48: =M48*(1+$Q$48) -> 1639.996 | O48: =N48*(1+$Q$48) -> 2026.8175 | P48: =O48*(1+$Q$48) -> 2504.8777 | Q48: =((M48/K48)^(1/3))-1 -> 0.23586737
A50: X | B50: Unlevered FCF | F50: =F41+F44-F46+F48 -> 3494.2125 | G50: =G41+G44-G46+G48 -> 5259.1097 | H50: =H41+H44-H46+H48 -> 13462.774 | I50: =I41+I44-I46+I48 -> 7032.5113 | J50: =J41+J44-J46+J48 -> 2020.6296 | K50: =K41+K44-K46+K48 -> 7190.8788 | L50: =L41+L44-L46+L48 -> 11565.218 | M50: =M41+M44-M46+M48 -> 14820.435 | ... P50: =P41+P44-P46+P48 -> 27417.954 | Q50: ='TGR and TV'!F35 -> 1146220
Q51: ^^TV in above cell
A53: X | B53: Calculating Enterprise Value
B54: Equity Value | D54: =NPV(C17,F50,G50,H50,I50,J50,K50,L50,M50,N50,O50,P50,Q50) -> 384926.41
B55: Debt Value | D55: =WACC!Q8 -> 4612
...

Sheet WACC
A1: ASML DCF | H1: * Notice that Cost of Equity is more variable than Cost of debt, think about it, cost of debt is fixed to coupons whereas cost of equity updates with Beta updates
H2: *Cost of Equity tailors a risk premium of the company, resulting in return expected by shareholders for risk they take on
H3: *Market Premium = The S&P 30 year risk in relation to lowest possible risk at RFR
H4: *COE= RFR+B(MRP) | J4: *MRP=Market Rate of Return-RFR | N4: *Reason Being: if Market cap exceeds EV, normalizing is needed
B5: WACC | H5: Cost of Equity | N5: Equity and Debt Weight Normalization
B6: Equity | N6: **Usually for tech companies
B7: % of Equity | E7: =Q11 -> 0.98713043 | H7: RFR | K7: 0.045 | N7: Equity Market cap | Q7: 353752.84
B8: Cost of Equity | E8: =K11 -> 0.1125 | H8: Beta | K8: =Q24*(1+(1-E14)*(Q8/Q7)) -> 1.5 | N8: Debt Market cap | Q8: 4612
H9: Market Premium | K9: 0.045 | N9: Total | Q9: =Q7+Q8 -> 358364.84
B10: Debt
B11: % of Debt | E11: =Q13 -> 0.012869566 | H11: Cost of Equity | K11: =K7+(K8*K9) -> 0.1125 | N11: Normalized % of Equity | Q11: =Q7/Q9 -> 0.98713043
B12: Cost of Debt | E12: =K27 -> 0.032223167
N13: Normalized % of Debt | Q13: =Q8/Q9 -> 0.012869566
B14: Tax Rate | E14: 0.1581
B16: Enterprise Value | E16: =Q9 -> 358364.84 | H16: *Amount of Bonds varies on sample size
H17: *Recommended sample size is >5, Larger = More accurate
H18: Cost of Debt | N18: Unlevered Beta
B19: WACC | E19: =(E7*E8)+(E11*E12*(1-E14)) -> 0.11140131
H20: Bond 1 %Coupon Yield | K20: 0.035232 | N20: Levered Beta | Q20: 1.5 | R20: Change Beta here
H21: Bond 2 %Coupon Yield | K21: 0.033104 | N21: Debt | Q21: =Q8 -> 4612
H22: Bond 3 %Coupon Yield | K22: 0.032422 | N22: Equity | Q22: =Q7 -> 353752.84
H23: Bond 4 %Coupon Yield | K23: 0.030634
H24: Bond 5 %Coupon Yield | K24: 0.031598 | N24: Unlevered Beta | Q24: =(Q20)/(1+(1-E14)*(Q21/Q22)) -> 1.4837145
H25: Bond 6 %Coupon Yield | K25: 0.030349
H27: Cost of Debt | K27: =AVERAGE(K20:K25) -> 0.032223167

Sheet TGR and TV
A1: ASML DCF
K3: Notes
A4: Works For Stable Businesses | K4: *2-4% is the usual range, although 2-4% is the usual range
A5: x | B5: TGR Calculation for Stable Comps | K5: *Use your own judgement within reason, Valuations are an ART, NOT A SCIENCE.
K6: *Remember to cite your source and have an explanation for all used numbers, they do vary
B7: Country of Origin GDP GR | K7: *Remember this is highly subjective, very dependent on stage of company growth
B8: Deviation | F8: =F18 -> 0 | K8: *Startups or tech companies will have a higher rate than a lawn mower company
K9: *IF THESE METHODS DO NOT WORK FOR YOUR COMPANY, INQUIRE WITH A FACULTY AND FIGURE OUT AN ALTERNATIVE SOLUTION
B10: TGR | F10: =F7-F8 -> 0 | K10: *Company GR is referring to their FCF Growth rate
K11: *GDP GR can be looked up
K12: *Terminal Multiple = Avg Ev/Ebitda over the projection period
B13: Deviation Formula | K13: *Note that Companies that have either negative FCF or are early in their life cycle are classified as "Unstable" in this model
K14: *Note that Companies that are mature or have positive FCF are classified as "Stable" in this model
B15: Company GR
B16: Country of Origin GDP GR | F16: =F7 -> 0 | K16: *Terminal Year EBITDA = the EBITDA of the year after your last FCF, Remember Terminal implies after projection period.
K17: *Yes, you will need to project this EBITDA value
A18: x | B18: Deviation | F18: =F15-F16 -> 0
A21: x | B21: Terminal Value for Stable Comps
B23: FCF last projection year
B24: TGR | F24: =F10 -> 0
B25: WACC | F25: =WACC!E19 -> 0.11140131
A27: x | B27: Terminal Value | F27: =(F23*(1+F24))/(F25-F24) -> 0
A29: Works For Unstable Businesses
A30: x | B30: Terminal Value for Unstable Comps
B32: EBITDA in Terminal year | F32: =DCF!Q32 -> 39221.874
B33: Terminal Multiple | F33: =E46 -> 29.224
A35: x | B35: Terminal Value | F35: =F32*F33 -> 1146220
B38: Multiple Calculation
B40: Ev/EBITDA YR 1 | E40: 23.49
B41: Ev/EBITDA YR 2 | E41: 28.92
B42: Ev/EBITDA YR 3 | E42: 30.28
B43: Ev/EBITDA YR 4 | E43: 33.23
B44: Ev/EBITDA YR 5 | E44: 30.2
B46: AVG Multiple | E46: =AVERAGE(E40:E44) -> 29.224
